2021-12-29 16:29:21,211 - INFO - generate_tags -  Starting script....
2021-12-29 16:29:21,211 - INFO - generate_tags -  Starting script....
2021-12-29 16:29:21,211 - DEBUG - generate_tags -  Retrieving config...
2021-12-29 16:29:21,211 - DEBUG - generate_tags -  Retrieving config...
2021-12-29 16:29:41,193 - INFO - generate_tags -  Starting script....
2021-12-29 16:29:41,193 - INFO - generate_tags -  Starting script....
2021-12-29 16:29:41,194 - DEBUG - generate_tags -  Retrieving config...
2021-12-29 16:29:41,194 - DEBUG - generate_tags -  Retrieving config...
2021-12-29 16:29:41,194 - ERROR - generate_tags -  A general error has occured: 'config_handler' object has no attribute 'read_config'
Traceback (most recent call last):
  File "/Users/philippreske/Documents/Projects/piwigo_image_tagger/generate_tags.py", line 192, in <module>
    tg.main()
  File "/Users/philippreske/Documents/Projects/piwigo_image_tagger/generate_tags.py", line 28, in main
    self.conf = ch.config_handler()
  File "/Users/philippreske/Documents/Projects/piwigo_image_tagger/lib/config_handler.py", line 36, in __init__
    self.read_config(config=self.config, souce_file=self.config_file)
AttributeError: 'config_handler' object has no attribute 'read_config'
2021-12-29 16:29:41,194 - ERROR - generate_tags -  A general error has occured: 'config_handler' object has no attribute 'read_config'
Traceback (most recent call last):
  File "/Users/philippreske/Documents/Projects/piwigo_image_tagger/generate_tags.py", line 192, in <module>
    tg.main()
  File "/Users/philippreske/Documents/Projects/piwigo_image_tagger/generate_tags.py", line 28, in main
    self.conf = ch.config_handler()
  File "/Users/philippreske/Documents/Projects/piwigo_image_tagger/lib/config_handler.py", line 36, in __init__
    self.read_config(config=self.config, souce_file=self.config_file)
AttributeError: 'config_handler' object has no attribute 'read_config'
2021-12-29 16:30:59,408 - INFO - generate_tags -  Starting script....
2021-12-29 16:30:59,408 - INFO - generate_tags -  Starting script....
2021-12-29 16:30:59,408 - DEBUG - generate_tags -  Retrieving config...
2021-12-29 16:30:59,408 - DEBUG - generate_tags -  Retrieving config...
2021-12-29 16:30:59,409 - ERROR - generate_tags -  A general error has occured: read_config_from_file() got an unexpected keyword argument 'souce_file'
Traceback (most recent call last):
  File "/Users/philippreske/Documents/Projects/piwigo_image_tagger/generate_tags.py", line 192, in <module>
    tg.main()
  File "/Users/philippreske/Documents/Projects/piwigo_image_tagger/generate_tags.py", line 28, in main
    self.conf = ch.config_handler()
  File "/Users/philippreske/Documents/Projects/piwigo_image_tagger/lib/config_handler.py", line 36, in __init__
    self.read_config_from_file(config=self.config, souce_file=self.config_file)
TypeError: read_config_from_file() got an unexpected keyword argument 'souce_file'
2021-12-29 16:30:59,409 - ERROR - generate_tags -  A general error has occured: read_config_from_file() got an unexpected keyword argument 'souce_file'
Traceback (most recent call last):
  File "/Users/philippreske/Documents/Projects/piwigo_image_tagger/generate_tags.py", line 192, in <module>
    tg.main()
  File "/Users/philippreske/Documents/Projects/piwigo_image_tagger/generate_tags.py", line 28, in main
    self.conf = ch.config_handler()
  File "/Users/philippreske/Documents/Projects/piwigo_image_tagger/lib/config_handler.py", line 36, in __init__
    self.read_config_from_file(config=self.config, souce_file=self.config_file)
TypeError: read_config_from_file() got an unexpected keyword argument 'souce_file'
2021-12-29 16:31:12,092 - INFO - generate_tags -  Starting script....
2021-12-29 16:31:12,092 - INFO - generate_tags -  Starting script....
2021-12-29 16:31:12,092 - DEBUG - generate_tags -  Retrieving config...
2021-12-29 16:31:12,092 - DEBUG - generate_tags -  Retrieving config...
2021-12-29 16:31:12,093 - INFO - config_handler -  config loaded with 0 records
2021-12-29 16:31:12,093 - INFO - config_handler -  config loaded with 0 records
2021-12-29 16:31:12,093 - INFO - config_handler -  processed_image_ids loaded with 0 records
2021-12-29 16:31:12,093 - INFO - config_handler -  processed_image_ids loaded with 0 records
2021-12-29 16:31:12,094 - INFO - config_handler -  translations loaded with 0 records
2021-12-29 16:31:12,094 - INFO - config_handler -  translations loaded with 0 records
2021-12-29 16:31:12,094 - ERROR - generate_tags -  A general error has occured: argument of type 'config_handler' is not iterable
Traceback (most recent call last):
  File "/Users/philippreske/Documents/Projects/piwigo_image_tagger/generate_tags.py", line 192, in <module>
    tg.main()
  File "/Users/philippreske/Documents/Projects/piwigo_image_tagger/generate_tags.py", line 29, in main
    self.working_directory = str(self.conf.get_config_value(config=self.conf, key="working_directory", create_if_missing=True))
  File "/Users/philippreske/Documents/Projects/piwigo_image_tagger/lib/config_handler.py", line 50, in get_config_value
    if key in config:
TypeError: argument of type 'config_handler' is not iterable
2021-12-29 16:31:12,094 - ERROR - generate_tags -  A general error has occured: argument of type 'config_handler' is not iterable
Traceback (most recent call last):
  File "/Users/philippreske/Documents/Projects/piwigo_image_tagger/generate_tags.py", line 192, in <module>
    tg.main()
  File "/Users/philippreske/Documents/Projects/piwigo_image_tagger/generate_tags.py", line 29, in main
    self.working_directory = str(self.conf.get_config_value(config=self.conf, key="working_directory", create_if_missing=True))
  File "/Users/philippreske/Documents/Projects/piwigo_image_tagger/lib/config_handler.py", line 50, in get_config_value
    if key in config:
TypeError: argument of type 'config_handler' is not iterable
2021-12-29 16:34:58,441 - INFO - generate_tags -  Starting script....
2021-12-29 16:34:58,441 - INFO - generate_tags -  Starting script....
2021-12-29 16:34:58,441 - DEBUG - generate_tags -  Retrieving config...
2021-12-29 16:34:58,441 - DEBUG - generate_tags -  Retrieving config...
2021-12-29 16:34:58,442 - INFO - config_handler -  config loaded with 0 records
2021-12-29 16:34:58,442 - INFO - config_handler -  config loaded with 0 records
2021-12-29 16:34:58,443 - INFO - config_handler -  processed_image_ids loaded with 0 records
2021-12-29 16:34:58,443 - INFO - config_handler -  processed_image_ids loaded with 0 records
2021-12-29 16:34:58,443 - INFO - config_handler -  translations loaded with 0 records
2021-12-29 16:34:58,443 - INFO - config_handler -  translations loaded with 0 records
2021-12-29 16:34:58,443 - ERROR - generate_tags -  A general error has occured: 'NoneType' object is not iterable
Traceback (most recent call last):
  File "/Users/philippreske/Documents/Projects/piwigo_image_tagger/generate_tags.py", line 192, in <module>
    tg.main()
  File "/Users/philippreske/Documents/Projects/piwigo_image_tagger/generate_tags.py", line 30, in main
    self.image_file_extensions = list(self.conf_handler.get_config_value(config=self.conf_handler.config, key="image_file_extensions", create_if_missing=True))
TypeError: 'NoneType' object is not iterable
2021-12-29 16:34:58,443 - ERROR - generate_tags -  A general error has occured: 'NoneType' object is not iterable
Traceback (most recent call last):
  File "/Users/philippreske/Documents/Projects/piwigo_image_tagger/generate_tags.py", line 192, in <module>
    tg.main()
  File "/Users/philippreske/Documents/Projects/piwigo_image_tagger/generate_tags.py", line 30, in main
    self.image_file_extensions = list(self.conf_handler.get_config_value(config=self.conf_handler.config, key="image_file_extensions", create_if_missing=True))
TypeError: 'NoneType' object is not iterable
2021-12-29 16:35:19,020 - INFO - generate_tags -  Starting script....
2021-12-29 16:35:19,020 - INFO - generate_tags -  Starting script....
2021-12-29 16:35:19,021 - DEBUG - generate_tags -  Retrieving config...
2021-12-29 16:35:19,021 - DEBUG - generate_tags -  Retrieving config...
2021-12-29 16:35:19,022 - INFO - config_handler -  config loaded with 0 records
2021-12-29 16:35:19,022 - INFO - config_handler -  config loaded with 0 records
2021-12-29 16:35:19,022 - INFO - config_handler -  processed_image_ids loaded with 0 records
2021-12-29 16:35:19,022 - INFO - config_handler -  processed_image_ids loaded with 0 records
2021-12-29 16:35:19,023 - INFO - config_handler -  translations loaded with 0 records
2021-12-29 16:35:19,023 - INFO - config_handler -  translations loaded with 0 records
2021-12-29 16:35:33,022 - ERROR - generate_tags -  A general error has occured: 'NoneType' object is not iterable
Traceback (most recent call last):
  File "/Users/philippreske/Documents/Projects/piwigo_image_tagger/generate_tags.py", line 192, in <module>
    tg.main()
  File "/Users/philippreske/Documents/Projects/piwigo_image_tagger/generate_tags.py", line 30, in main
    self.image_file_extensions = list(self.conf_handler.get_config_value(config=self.conf_handler.config, key="image_file_extensions", create_if_missing=True))
TypeError: 'NoneType' object is not iterable
2021-12-29 16:35:33,022 - ERROR - generate_tags -  A general error has occured: 'NoneType' object is not iterable
Traceback (most recent call last):
  File "/Users/philippreske/Documents/Projects/piwigo_image_tagger/generate_tags.py", line 192, in <module>
    tg.main()
  File "/Users/philippreske/Documents/Projects/piwigo_image_tagger/generate_tags.py", line 30, in main
    self.image_file_extensions = list(self.conf_handler.get_config_value(config=self.conf_handler.config, key="image_file_extensions", create_if_missing=True))
TypeError: 'NoneType' object is not iterable
2021-12-29 16:37:39,120 - INFO - generate_tags -  Starting script....
2021-12-29 16:37:39,120 - INFO - generate_tags -  Starting script....
2021-12-29 16:37:39,120 - DEBUG - generate_tags -  Retrieving config...
2021-12-29 16:37:39,120 - DEBUG - generate_tags -  Retrieving config...
2021-12-29 16:37:39,121 - INFO - config_handler -  config loaded with 0 records
2021-12-29 16:37:39,121 - INFO - config_handler -  config loaded with 0 records
2021-12-29 16:37:39,122 - INFO - config_handler -  processed_image_ids loaded with 0 records
2021-12-29 16:37:39,122 - INFO - config_handler -  processed_image_ids loaded with 0 records
2021-12-29 16:37:39,122 - INFO - config_handler -  translations loaded with 0 records
2021-12-29 16:37:39,122 - INFO - config_handler -  translations loaded with 0 records
2021-12-29 16:37:41,631 - ERROR - generate_tags -  A general error has occured: Invalid URL 'None/ws.php?': No schema supplied. Perhaps you meant http://None/ws.php??
Traceback (most recent call last):
  File "/Users/philippreske/Documents/Projects/piwigo_image_tagger/generate_tags.py", line 192, in <module>
    tg.main()
  File "/Users/philippreske/Documents/Projects/piwigo_image_tagger/generate_tags.py", line 47, in main
    self.pw.pwg.session.login(username=self.piwigo_user, password=self.piwigo_pass)
  File "/Users/philippreske/Documents/Projects/piwigo_image_tagger/.venv/lib/python3.9/site-packages/piwigo/ws.py", line 96, in checking
    return fn(self, **kw)
  File "/Users/philippreske/Documents/Projects/piwigo_image_tagger/.venv/lib/python3.9/site-packages/piwigo/ws.py", line 121, in __call__
    r = requests.get(url, params=params, data=data, files=files, cookies=self._pwg._cookies)
  File "/Users/philippreske/Documents/Projects/piwigo_image_tagger/.venv/lib/python3.9/site-packages/requests/api.py", line 75, in get
    return request('get', url, params=params, **kwargs)
  File "/Users/philippreske/Documents/Projects/piwigo_image_tagger/.venv/lib/python3.9/site-packages/requests/api.py", line 61, in request
    return session.request(method=method, url=url, **kwargs)
  File "/Users/philippreske/Documents/Projects/piwigo_image_tagger/.venv/lib/python3.9/site-packages/requests/sessions.py", line 528, in request
    prep = self.prepare_request(req)
  File "/Users/philippreske/Documents/Projects/piwigo_image_tagger/.venv/lib/python3.9/site-packages/requests/sessions.py", line 456, in prepare_request
    p.prepare(
  File "/Users/philippreske/Documents/Projects/piwigo_image_tagger/.venv/lib/python3.9/site-packages/requests/models.py", line 316, in prepare
    self.prepare_url(url, params)
  File "/Users/philippreske/Documents/Projects/piwigo_image_tagger/.venv/lib/python3.9/site-packages/requests/models.py", line 390, in prepare_url
    raise MissingSchema(error)
requests.exceptions.MissingSchema: Invalid URL 'None/ws.php?': No schema supplied. Perhaps you meant http://None/ws.php??
2021-12-29 16:37:41,631 - ERROR - generate_tags -  A general error has occured: Invalid URL 'None/ws.php?': No schema supplied. Perhaps you meant http://None/ws.php??
Traceback (most recent call last):
  File "/Users/philippreske/Documents/Projects/piwigo_image_tagger/generate_tags.py", line 192, in <module>
    tg.main()
  File "/Users/philippreske/Documents/Projects/piwigo_image_tagger/generate_tags.py", line 47, in main
    self.pw.pwg.session.login(username=self.piwigo_user, password=self.piwigo_pass)
  File "/Users/philippreske/Documents/Projects/piwigo_image_tagger/.venv/lib/python3.9/site-packages/piwigo/ws.py", line 96, in checking
    return fn(self, **kw)
  File "/Users/philippreske/Documents/Projects/piwigo_image_tagger/.venv/lib/python3.9/site-packages/piwigo/ws.py", line 121, in __call__
    r = requests.get(url, params=params, data=data, files=files, cookies=self._pwg._cookies)
  File "/Users/philippreske/Documents/Projects/piwigo_image_tagger/.venv/lib/python3.9/site-packages/requests/api.py", line 75, in get
    return request('get', url, params=params, **kwargs)
  File "/Users/philippreske/Documents/Projects/piwigo_image_tagger/.venv/lib/python3.9/site-packages/requests/api.py", line 61, in request
    return session.request(method=method, url=url, **kwargs)
  File "/Users/philippreske/Documents/Projects/piwigo_image_tagger/.venv/lib/python3.9/site-packages/requests/sessions.py", line 528, in request
    prep = self.prepare_request(req)
  File "/Users/philippreske/Documents/Projects/piwigo_image_tagger/.venv/lib/python3.9/site-packages/requests/sessions.py", line 456, in prepare_request
    p.prepare(
  File "/Users/philippreske/Documents/Projects/piwigo_image_tagger/.venv/lib/python3.9/site-packages/requests/models.py", line 316, in prepare
    self.prepare_url(url, params)
  File "/Users/philippreske/Documents/Projects/piwigo_image_tagger/.venv/lib/python3.9/site-packages/requests/models.py", line 390, in prepare_url
    raise MissingSchema(error)
requests.exceptions.MissingSchema: Invalid URL 'None/ws.php?': No schema supplied. Perhaps you meant http://None/ws.php??
